Workbook

Sheet Painel
A1: PLANO DE DESMOBILIZAÇÃO
A5: EQUIPES ATUAIS 87 | D5: SAÍDAS PREVISTAS 31 | G5: EQUIPES FINAIS 56 | J5: VIATURAS MAPEADAS 70
A10: CENÁRIO FINANCEIRO | H10: REEQUILÍBRIO POR TIPO DE EQUIPE
A11: VALOR 2026 ATUAL R$ 5.276.284,97 | D11: VALOR 2026 PÓS-DESMOBILIZAÇÃO R$ 3.944.192,763 | H11: Moto Corte | I11: 0.81 | L11: Emergência | M11: 0.29
H12: Comercial | I12: 0.21 | L12: Grupo A | M12: 0.28
A17: Mês | B17: Equipes que saem | C17: Acumulado | D17: Equipes restantes | E17: Redução sem reequilíbrio | H17: Mês | I17: Contrato sem reequilíbrio | J17: Contrato com reequilíbrio
A18: ='Resumo Mensal'!A4 -> 46204 | B18: ='Resumo Mensal'!B4 -> 1 | C18: ='Resumo Mensal'!C4 -> 1 | D18: ='Resumo Mensal'!D4 -> 87 | E18: ='Resumo Mensal'!E4 -> 75054.508 | H18: ='Resumo Mensal'!A4 -> 46204 | I18: ='Resumo Mensal'!G4 -> 5201230.5 | J18: ='Resumo Mensal'!H4 -> 6754559.2
A19: ='Resumo Mensal'!A5 -> 46235 | B19: ='Resumo Mensal'!B5 -> 3 | C19: ='Resumo Mensal'!C5 -> 4 | D19: ='Resumo Mensal'!D5 -> 84 | E19: ='Resumo Mensal'!E5 -> 200811.31 | H19: ='Resumo Mensal'!A5 -> 46235 | I19: ='Resumo Mensal'!G5 -> 5000419.1 | J19: ='Resumo Mensal'!H5 -> 6495512.6
A20: ='Resumo Mensal'!A6 -> 46266 | B20: ='Resumo Mensal'!B6 -> 4 | C20: ='Resumo Mensal'!C6 -> 8 | D20: ='Resumo Mensal'!D6 -> 80 | E20: ='Resumo Mensal'!E6 -> 300218.03 | H20: ='Resumo Mensal'!A6 -> 46266 | I20: ='Resumo Mensal'!G6 -> 4700201.1 | J20: ='Resumo Mensal'!H6 -> 6108231.3
A21: ='Resumo Mensal'!A7 -> 46296 | B21: ='Resumo Mensal'!B7 -> 8 | C21: ='Resumo Mensal'!C7 -> 16 | D21: ='Resumo Mensal'!D7 -> 72 | E21: ='Resumo Mensal'!E7 -> 576083.85 | H21: ='Resumo Mensal'!A7 -> 46296 | I21: ='Resumo Mensal'!G7 -> 4124117.3 | J21: ='Resumo Mensal'!H7 -> 5365083.2
A22: ='Resumo Mensal'!A8 -> 46327 | B22: ='Resumo Mensal'!B8 -> 11 | C22: ='Resumo Mensal'!C8 -> 27 | D22: ='Resumo Mensal'!D8 -> 61 | E22: ='Resumo Mensal'!E8 -> 801247.38 | H22: ='Resumo Mensal'!A8 -> 46327 | I22: ='Resumo Mensal'!G8 -> 3322869.9 | J22: ='Resumo Mensal'!H8 -> 4331474
A23: ='Resumo Mensal'!A9 -> 46357 | B23: ='Resumo Mensal'!B9 -> 4 | C23: ='Resumo Mensal'!C9 -> 31 | D23: ='Resumo Mensal'!D9 -> 57 | E23: ='Resumo Mensal'!E9 -> 300218.03 | H23: ='Resumo Mensal'!A9 -> 46357 | I23: ='Resumo Mensal'!G9 -> 3022651.9 | J23: ='Resumo Mensal'!H9 -> 3944192.8

Sheet Cortes
A1: Total Cortes Débito e Diferente de Débito
A2: Dias aptos a corte | B2: 17 | C2: 15 | D2: 16 | E2: 15 | F2: 16 | G2: 17 | H2: 18 | I2: 17 | J2: 18 | K2: 17 | L2: 16 | M2: 18 | R2: lucila
A3: UO | B3: Jan | C3: Fev | D3: Mar | E3: Abr | F3: Mai | G3: Jun | H3: Jul | I3: Ago | J3: Set | K3: Out | L3: Nov | M3: Dez | N3: Total | O3: Média Mês | P3: Meta/dia | Q3: Equipes | R3: Qtd Por Equipe Enel | S3: Qtd Por Equipe - Control | T3: Qtd Por Equipe - Control | U3: Atual | V3: Incremento | W3: Total Atual | X3: Deficit | Y3: Deficit Corte/dia | Z3: Qtd Equipes Multskill | AA3: Qtd Corte/dia Equipes Multiskill
A4: Total | B4: 6390.4151 | C4: 5638.6016 | D4: 6014.5084 | E4: 5638.6016 | F4: 6014.5084 | G4: 6390.4151 | H4: 6766.3219 | I4: 6390.4151 | J4: 6766.3219 | K4: 6390.4151 | L4: 6014.5084 | M4: 6766.3219 | N4: 75181.355 | O4: 6265.1129 | P4: 417.67419 | Q4: 26.946722 | R4: 15.5 | S4: 25 | T4: =SUM(T5:T8) -> 16.706968 | U4: =SUM(U5:U8) -> 9 | V4: =SUM(V5:V8) -> 4 | W4: =SUM(U4:V4) -> 13 | X4: =T4-W4 -> 3.7069677 | Y4: =SUM(Y5:Y7) -> 85.814866 | Z4: 34 | AA4: 85.814866
A5: Canindé | B5: 1775.0411 | C5: 1566.2128 | D5: 1670.627 | E5: 1566.2128 | F5: 1670.627 | G5: 1775.0411 | H5: 1879.4553 | I5: 1775.0411 | J5: 1879.4553 | K5: 1775.0411 | L5: 1670.627 | M5: 1879.4553 | N5: 20882.837 | O5: 1740.2364 | P5: 116.01576 | Q5: 7.4848878 | R5: =P5/Q5 -> 15.5 | S5: 25 | T5: =P5/S5 -> 4.6406305 | U5: =SUM(N15:O15) -> 2 | V5: 1 | W5: =SUM(U5:V5) -> 3 | X5: =T5-W5 -> 1.6406305 | Y5: =X5*S5 -> 41.015761 | Z5: =T15 -> 10 | AA5: =Y5/Z5 -> 4.1015761
A6: Nova russas | B6: 1917.8337 | C6: 1692.2062 | D6: 1805.02 | E6: 1692.2062 | F6: 1805.02 | G6: 1917.8337 | H6: 2030.6475 | I6: 1917.8337 | J6: 2030.6475 | K6: 1917.8337 | L6: 1805.02 | M6: 2030.6475 | N6: 22562.75 | O6: 1880.2292 | P6: 125.34861 | Q6: 8.0870071 | R6: =P6/Q6 -> 15.5 | S6: 25 | T6: =P6/S6 -> 5.0139444 | U6: =SUM(N16:O16) -> 3 | V6: 1 | W6: =SUM(U6:V6) -> 4 | X6: =T6-W6 -> 1.0139444 | Y6: =X6*S6 -> 25.34861 | Z6: =T18 -> 10 | AA6: =Y6/Z6 -> 2.534861
A7: Crateús | B7: 1062.5926 | C7: 937.58168 | D7: 1000.0871 | E7: 937.58168 | F7: 1000.0871 | G7: 1062.5926 | H7: 1125.098 | I7: 1062.5926 | J7: 1125.098 | K7: 1062.5926 | L7: 1000.0871 | M7: 1125.098 | N7: 12501.089 | O7: 1041.7574 | P7: 69.450495 | Q7: 4.4806771 | R7: =P7/Q7 -> 15.5 | S7: 25 | T7: =P7/S7 -> 2.7780198 | U7: =SUM(N17:O17) -> 1 | V7: 1 | W7: =SUM(U7:V7) -> 2 | X7: =T7-W7 -> 0.77801979 | Y7: =X7*S7 -> 19.450495 | Z7: =T17 -> 5 | AA7: =Y7/Z7 -> 3.890099
A8: Quixadá | B8: 1634.9477 | C8: 1442.6009 | D8: 1538.7743 | E8: 1442.6009 | F8: 1538.7743 | G8: 1634.9477 | H8: 1731.1211 | I8: 1634.9477 | J8: 1731.1211 | K8: 1634.9477 | L8: 1538.7743 | M8: 1731.1211 | N8: 19234.679 | O8: 1602.8899 | P8: 106.85933 | Q8: 6.8941501 | R8: =P8/Q8 -> 15.5 | S8: 25 | T8: =P8/S8 -> 4.274373 | U8: =SUM(N18:O18) -> 3 | V8: 1 | W8: =SUM(U8:V8) -> 4 | X8: =T8-W8 -> 0.27437303 | Y8: =X8*S8 -> 6.8593258 | Z8: =T16 -> 9 | AA8: =Y8/Z8 -> 0.76214731
A13: Divisão Atual | E13: Divisão Proposta | G13: Divisão Proposta - Control | N13: Divisão Atual - Control | R13: Divisão Proposta - Control
A14: Regional | B14: Moto | C14: Carro | D14: Total | E14: Acréscimo de Equipes (Proposta - Enel) | F14: Proposta Total - Enel | G14: Acréscimo de Equipes (Proposta - Control) | H14: Proposta Total - Control | M14: Regional | N14: CORTE MOTO - ATUAL | O14: CORTE SAVEIRO - ATUAL | P14: DEMAIS SERVIÇOS - ATUAL | Q14: Total - Atual | R14: CORTE SAVEIRO - PROPOSTO | S14: CORTE MOTO - PROPOSTO | T14: DEMAIS SERVIÇOS - PROPOSTO | U14: Total - Proposto
A15: Canindé | B15: 2 | C15: 10 | D15: =SUM(B15:C15) -> 12 | E15: 3.0274272 | F15: =E15+D15 -> 15.027427 | G15: 1 | H15: =G15+D15 -> 13 | M15: Canindé | N15: 0 | O15: 2 | P15: 10 | Q15: =SUM(N15:P15) -> 12 | R15: 3 | S15: 0 | T15: 10 | U15: =SUM(R15:T15) -> 13
A16: Quixadá | B16: 3 | C16: 9 | D16: =SUM(B16:C16) -> 12 | E16: 4 | F16: =E16+D16 -> 16 | G16: 1 | H16: =G16+D16 -> 13 | M16: Quixadá | N16: 2 | O16: 1 | P16: 9 | Q16: =SUM(N16:P16) -> 12 | R16: 2 | S16: 2 | T16: 9 | U16: =SUM(R16:T16) -> 13
A17: Crateús | B17: 1 | C17: 5 | D17: =SUM(B17:C17) -> 6 | E17: 3 | F17: =E17+D17 -> 9 | G17: 1 | H17: =G17+D17 -> 7 | M17: Crateús | N17: 1 | O17: 0 | P17: 5 | Q17: =SUM(N17:P17) -> 6 | R17: 1 | S17: 1 | T17: 5 | U17: =SUM(R17:T17) -> 7
A18: Nova Russas | B18: 3 | C18: 10 | D18: =SUM(B18:C18) -> 13 | E18: 4 | F18: =E18+D18 -> 17 | G18: 1 | H18: =G18+D18 -> 14 | M18: Nova Russas | N18: 2 | O18: 1 | P18: 10 | Q18: =SUM(N18:P18) -> 13 | R18: 2 | S18: 2 | T18: 10 | U18: =SUM(R18:T18) -> 14
A19: Total | B19: =SUM(B15:B18) -> 9 | C19: =SUM(C15:C18) -> 34 | D19: =SUM(B19:C19) -> 43 | E19: 14.027427 | F19: =E19+D19 -> 57.027427 | G19: =SUM(G15:G18) -> 4 | H19: =G19+D19 -> 47 | M19: Total | N19: =SUM(N15:N18) -> 5 | O19: =SUM(O15:O18) -> 4 | P19: =SUM(P15:P18) -> 34 | Q19: =SUM(Q15:Q18) -> 43 | R19: =SUM(R15:R18) -> 8 | S19: =SUM(S15:S18) -> 5 | T19: =SUM(T15:T18) -> 34 | U19: =SUM(U15:U18) -> 47

Sheet Base - Equipes Placas
A1: Equipes | B1: Estrutura | C1: Subprocesso | D1: Supervisor | E1: Polo | F1: Localidade | G1: MOBILIZAÇÃO | H1: DESMOBIZAÇÃO | I1: PLACA | J1: CARRO COMPARTILHADO | K1: Status Viatura | L1: Meta Hoje | M1: Meta pós Reajuste | N1: Reajuste
A2: CND-LB-20B | B2: Vistoria Virtual - Eloisa | C2: CORTE, RELIGA, LIGAÇÃO NOVA | D2: LUCILA MARIA CABRAL ARAUJO | E2: CANINDE | F2: CANINDE | G2: MOBILIZADA | H2: NÃO | I2: SEM PLACA | J2: SEM CARRO | K2: MANTER VIATURA | L2: 0 | M2: =Tabela1[[#This Row],[Meta Hoje]]*Tabela1[[#This Row],[Reajuste]] -> 0 | N2: =_xlfn.XLOOKUP(Tabela1[[#This Row],[Subprocesso]],Ajuste!A:A,Ajuste!B:B,0) -> 1.21
A3: CND-LM-28B | B3: Pick Up Leve 4x2 | C3: CORTE, RELIGA, LIGAÇÃO NOVA | D3: FELIPE PAIXAO DA SILVA | E3: CANINDE | F3: CANINDE | G3: MOBILIZADA | H3: NÃO | I3: TDU6A09 | J3: NÃO COMPARTILHA | K3: MANTER VIATURA | L3: 51105.432 | M3: =Tabela1[[#This Row],[Meta Hoje]]*Tabela1[[#This Row],[Reajuste]] -> 61837.573 | N3: =_xlfn.XLOOKUP(Tabela1[[#This Row],[Subprocesso]],Ajuste!A:A,Ajuste!B:B,0) -> 1.21
A4: QXD-LM-24B | B4: Pick Up Leve 4x2 | C4: CORTE, RELIGA, LIGAÇÃO NOVA | D4: DIEGO ALAN ANDRE BATISTA | E4: QUIXADA | F4: QUIXADÁ | G4: MOBILIZADA | H4: NÃO | I4: TDU6A92 | J4: NÃO COMPARTILHA | K4: MANTER VIATURA | L4: 51105.432 | M4: =Tabela1[[#This Row],[Meta Hoje]]*Tabela1[[#This Row],[Reajuste]] -> 61837.573 | N4: =_xlfn.XLOOKUP(Tabela1[[#This Row],[Subprocesso]],Ajuste!A:A,Ajuste!B:B,0) -> 1.21
A5: CND-LM-25B | B5: Pick Up Leve 4x2 | C5: CORTE, RELIGA, LIGAÇÃO NOVA | D5: FELIPE PAIXAO DA SILVA | E5: CANINDE | F5: CANINDE | G5: MOBILIZADA | H5: NÃO | I5: TDU6A93 | J5: NÃO COMPARTILHA | K5: MANTER VIATURA | L5: 51105.432 | M5: =Tabela1[[#This Row],[Meta Hoje]]*Tabela1[[#This Row],[Reajuste]] -> 61837.573 | N5: =_xlfn.XLOOKUP(Tabela1[[#This Row],[Subprocesso]],Ajuste!A:A,Ajuste!B:B,0) -> 1.21
A6: CND-MO-22B | B6: Moto | C6: MOTO CORTE | D6: FELIPE PAIXAO DA SILVA | E6: CANINDE | F6: CANINDE | G6: MOBILIZADA | H6: NÃO | I6: TDU6A94 | J6: NÃO COMPARTILHA | K6: MANTER VIATURA | L6: 39477.95 | M6: =Tabela1[[#This Row],[Meta Hoje]]*Tabela1[[#This Row],[Reajuste]] -> 71455.09 | N6: =_xlfn.XLOOKUP(Tabela1[[#This Row],[Subprocesso]],Ajuste!A:A,Ajuste!B:B,0) -> 1.81
A7: CAT-LM-25B | B7: Pick Up Leve 4x2 | C7: CORTE, RELIGA, LIGAÇÃO NOVA | D7: RODENBERG ROSENDO DE MORAIS | E7: CRATEUS | F7: CRATEUS | G7: MOBILIZADA | H7: NÃO | I7: TDU6A95 | J7: NÃO COMPARTILHA | K7: MANTER VIATURA | L7: 51105.432 | M7: =Tabela1[[#This Row],[Meta Hoje]]*Tabela1[[#This Row],[Reajuste]] -> 61837.573 | N7: =_xlfn.XLOOKUP(Tabela1[[#This Row],[Subprocesso]],Ajuste!A:A,Ajuste!B:B,0) -> 1.21
A8: QXD-MO-23B | B8: Moto | C8: MOTO CORTE | D8: DIEGO ALAN ANDRE BATISTA | E8: QUIXADA | F8: QUIXADA | G8: MOBILIZADA | H8: NÃO | I8: TDU6A96 | J8: NÃO COMPARTILHA | K8: MANTER VIATURA | L8: 39477.95 | M8: =Tabela1[[#This Row],[Meta Hoje]]*Tabela1[[#This Row],[Reajuste]] -> 71455.09 | N8: =_xlfn.XLOOKUP(Tabela1[[#This Row],[Subprocesso]],Ajuste!A:A,Ajuste!B:B,0) -> 1.81
A9: CND-LM-22B | B9: Pick Up Leve 4x2 | C9: CORTE, RELIGA, LIGAÇÃO NOVA | D9: FELIPE PAIXAO DA SILVA | E9: CANINDE | F9: CANINDE | G9: MOBILIZADA | H9: NÃO | I9: TDU6A97 | J9: NÃO COMPARTILHA | K9: MANTER VIATURA | L9: 51105.432 | M9: =Tabela1[[#This Row],[Meta Hoje]]*Tabela1[[#This Row],[Reajuste]] -> 61837.573 | N9: =_xlfn.XLOOKUP(Tabela1[[#This Row],[Subprocesso]],Ajuste!A:A,Ajuste!B:B,0) -> 1.21
A10: NVR-LM-22B | B10: Pick Up Leve 4x2 | C10: CORTE, RELIGA, LIGAÇÃO NOVA | D10: ANTONIO REGIS LEMOS OLIVEIRA | E10: NOVA RUSSAS | F10: NOVA RUSSAS | G10: MOBILIZADA | H10: NÃO | I10: TDU6A99 | J10: NÃO COMPARTILHA | K10: MANTER VIATURA | L10: 51105.432 | M10: =Tabela1[[#This Row],[Meta Hoje]]*Tabela1[[#This Row],[Reajuste]] -> 61837.573 | N10: =_xlfn.XLOOKUP(Tabela1[[#This Row],[Subprocesso]],Ajuste!A:A,Ajuste!B:B,0) -> 1.21
A11: CNB-LM-27B | B11: Pick Up Leve 4x4 - Escada Central | C11: CORTE, RELIGA, LIGAÇÃO NOVA | D11: FELIPE PAIXAO DA SILVA | E11: CANINDE | F11: BOA VIAGEM | G11: MOBILIZADA | H11: NÃO | I11: TDU6B00 | J11: NÃO COMPARTILHA | K11: MANTER VIATURA | L11: 51105.432 | M11: =Tabela1[[#This Row],[Meta Hoje]]*Tabela1[[#This Row],[Reajuste]] -> 61837.573 | N11: =_xlfn.XLOOKUP(Tabela1[[#This Row],[Subprocesso]],Ajuste!A:A,Ajuste!B:B,0) -> 1.21
A12: CAT-LM-23B | B12: Pick Up Leve 4x2 | C12: CORTE, RELIGA, LIGAÇÃO NOVA | D12: RODENBERG ROSENDO DE MORAIS | E12: CRATEUS | F12: CRATEUS | G12: MOBILIZADA | H12: NÃO | I12: TDU6B01 | J12: NÃO COMPARTILHA | K12: MANTER VIATURA | L12: 51105.432 | M12: =Tabela1[[#This Row],[Meta Hoje]]*Tabela1[[#This Row],[Reajuste]] -> 61837.573 | N12: =_xlfn.XLOOKUP(Tabela1[[#This Row],[Subprocesso]],Ajuste!A:A,Ajuste!B:B,0) -> 1.21
A13: NVR-MO-21B | B13: Moto | C13: MOTO CORTE | D13: ANTONIO REGIS LEMOS OLIVEIRA | E13: NOVA RUSSAS | F13: NOVA RUSSAS | G13: MOBILIZADA | H13: NÃO | I13: TDU6B02 | J13: NÃO COMPARTILHA | K13: MANTER VIATURA | L13: 39477.95 | M13: =Tabela1[[#This Row],[Meta Hoje]]*Tabela1[[#This Row],[Reajuste]] -> 71455.09 | N13: =_xlfn.XLOOKUP(Tabela1[[#This Row],[Subprocesso]],Ajuste!A:A,Ajuste!B:B,0) -> 1.81
... A36: GRUPO A | B36: Caminhão SKY | C36: GRUPO A | D36: FELIPE PAIXAO DA SILVA | E36: CANINDE | F36: CANINDE | G36: MOBILIZADA | H36: NÃO | I36: TES4E19 | J36: NÃO COMPARTILHA | K36: MANTER VIATURA | L36: 77815.924 | M36: =Tabela1[[#This Row],[Meta Hoje]]*Tabela1[[#This Row],[Reajuste]] -> 99604.382 | N36: =_xlfn.XLOOKUP(Tabela1[[#This Row],[Subprocesso]],Ajuste!A:A,Ajuste!B:B,0) -> 1.28
A37: NVM-RD-21B | B37: Pick Up Média 4x4 | C37: EMERGENCIA | D37: JEAN LIRA DE ARAUJO | E37: NOVA RUSSAS | F37: MONSENHOR TABOSA | G37: MOBILIZADA | H37: 46327 | I37: TIZ7G43 | J37: NÃO COMPARTILHA | K37: DEVOLVER VIATURA | L37: 75054.508 | M37: =Tabela1[[#This Row],[Meta Hoje]]*Tabela1[[#This Row],[Reajuste]] -> 96820.316 | N37: =_xlfn.XLOOKUP(Tabela1[[#This Row],[Subprocesso]],Ajuste!A:A,Ajuste!B:B,0) -> 1.29
A38: QXD-RD-21D | B38: Pick Up Média 4x4 | C38: EMERGENCIA | D38: ALEX DE OLIVEIRA LIMA | E38: QUIXADA | F38: QUIXADÁ | G38: MOBILIZADA | H38: NÃO | I38: TJB4F14 | J38: COMPARTILHA | K38: - | L38: 75054.508 | M38: =Tabela1[[#This Row],[Meta Hoje]]*Tabela1[[#This Row],[Reajuste]] -> 96820.316 | N38: =_xlfn.XLOOKUP(Tabela1[[#This Row],[Subprocesso]],Ajuste!A:A,Ajuste!B:B,0) -> 1.29
A39: QXD-RD-22B | B39: Pick Up Média 4x4 | C39: EMERGENCIA | D39: ALEX DE OLIVEIRA LIMA | E39: QUIXADA | F39: QUIXADÁ | G39: MOBILIZADA | H39: 46296 | I39: TJB4F14 | J39: COMPARTILHA | K39: DEVOLVER VIATURA | L39: 75054.508 | M39: =Tabela1[[#This Row],[Meta Hoje]]*Tabela1[[#This Row],[Reajuste]] -> 96820.316 | N39: =_xlfn.XLOOKUP(Tabela1[[#This Row],[Subprocesso]],Ajuste!A:A,Ajuste!B:B,0) -> 1.29
A40: NVV-RD-21B | B40: Pick Up Média 4x4 | C40: EMERGENCIA | D40: JEAN LIRA DE ARAUJO | E40: NOVA RUSSAS | F40: VARJOTA | G40: MOBILIZADA | H40: 46327 | I40: TJD1C62 | J40: COMPARTILHA | K40: DEVOLVER VIATURA | L40: 75054.508 | M40: =Tabela1[[#This Row],[Meta Hoje]]*Tabela1[[#This Row],[Reajuste]] -> 96820.316 | N40: =_xlfn.XLOOKUP(Tabela1[[#This Row],[Subprocesso]],Ajuste!A:A,Ajuste!B:B,0) -> 1.29
A41: NVV-RD-21C | B41: Pick Up Média 4x4 | C41: EMERGENCIA | D41: JEAN LIRA DE ARAUJO | E41: NOVA RUSSAS | F41: VARJOTA | G41: MOBILIZADA | H41: 46327 | I41: TJD1C62 | J41: COMPARTILHA | K41: - | L41: 75054.508 | M41: =Tabela1[[#This Row],[Meta Hoje]]*Tabela1[[#This Row],[Reajuste]] -> 96820.316 | N41: =_xlfn.XLOOKUP(Tabela1[[#This Row],[Subprocesso]],Ajuste!A:A,Ajuste!B:B,0) -> 1.29
A42: QXD-RD-23B | B42: Pick Up Média 4x4 TAC | C42: EMERGENCIA | D42: ALEX DE OLIVEIRA LIMA | E42: QUIXADA | F42: QUIXADA | G42: MOBILIZADA | H42: 46296 | I42: TJD6E41 | J42: COMPARTILHA | K42: MANTER VIATURA | L42: 50702.296 | M42: =Tabela1[[#This Row],[Meta Hoje]]*Tabela1[[#This Row],[Reajuste]] -> 65405.961 | N42: =_xlfn.XLOOKUP(Tabela1[[#This Row],[Subprocesso]],Ajuste!A:A,Ajuste!B:B,0) -> 1.29
A43: CAT-RD-23C | B43: Pick Up Média 4x4 | C43: EMERGENCIA | D43: RODENBERG ROSENDO DE MORAIS | E43: CRATEUS | F43: CRATEUS | G43: MOBILIZADA | H43: 46357 | I43: TJF4F81 | J43: COMPARTILHA | K43: DEVOLVER VIATURA | L43: 75054.508 | M43: =Tabela1[[#This Row],[Meta Hoje]]*Tabela1[[#This Row],[Reajuste]] -> 96820.316 | N43: =_xlfn.XLOOKUP(Tabela1[[#This Row],[Subprocesso]],Ajuste!A:A,Ajuste!B:B,0) -> 1.29
A44: CND-RD-23B | B44: Pick Up Média 4x4 | C44: EMERGENCIA | D44: SIDNEY DIAS BARROSO | E44: CANINDE | F44: CANINDE | G44: DESMOBILIZADA | H44: 46237 | I44: TJF6I34 | J44: DESMOBILIZADA | K44: MANTER VIATURA | L44: 50702.296 | M44: =Tabela1[[#This Row],[Meta Hoje]]*Tabela1[[#This Row],[Reajuste]] -> 65405.961 | N44: =_xlfn.XLOOKUP(Tabela1[[#This Row],[Subprocesso]],Ajuste!A:A,Ajuste!B:B,0) -> 1.29
A45: NVR-RD-21C | B45: Pick Up Média 4x4 | C45: EMERGENCIA | D45: JEAN LIRA DE ARAUJO | E45: NOVA RUSSAS | F45: NOVA RUSSAS | G45: MOBILIZADA | H45: 46327 | I45: TJF6I57 | J45: COMPARTILHA | K45: DEVOLVER VIATURA | L45: 75054.508 | M45: =Tabela1[[#This Row],[Meta Hoje]]*Tabela1[[#This Row],[Reajuste]] -> 96820.316 | N45: =_xlfn.XLOOKUP(Tabela1[[#This Row],[Subprocesso]],Ajuste!A:A,Ajuste!B:B,0) -> 1.29
A46: NVR-RD-23B | B46: Pick Up Média 4x4 | C46: EMERGENCIA | D46: JEAN LIRA DE ARAUJO | E46: NOVA RUSSAS | F46: NOVA RUSSAS | G46: MOBILIZADA | H46: 46327 | I46: TJF6I57 | J46: COMPARTILHA | K46: - | L46: 75054.508 | M46: =Tabela1[[#This Row],[Meta Hoje]]*Tabela1[[#This Row],[Reajuste]] -> 96820.316 | N46: =_xlfn.XLOOKUP(Tabela1[[#This Row],[Subprocesso]],Ajuste!A:A,Ajuste!B:B,0) -> 1.29
A47: CAT-RD-22C | B47: Pick Up Média 4x4 | C47: EMERGENCIA | D47: RODENBERG ROSENDO DE MORAIS | E47: CRATEUS | F47: CRATEUS | G47: MOBILIZADA | H47: 46357 | I47: TJK3A62 | J47: COMPARTILHA | K47: MANTER VIATURA | L47: 75054.508 | M47: =Tabela1[[#This Row],[Meta Hoje]]*Tabela1[[#This Row],[Reajuste]] -> 96820.316 | N47: =_xlfn.XLOOKUP(Tabela1[[#This Row],[Subprocesso]],Ajuste!A:A,Ajuste!B:B,0) -> 1.29
A48: CAT-RD-21B | B48: Pick Up Média 4x4 | C48: EMERGENCIA | D48: RODENBERG ROSENDO DE MORAIS | E48: CRATEUS | F48: CRATEUS | G48: MOBILIZADA | H48: NÃO | I48: TJN5B95 | J48: NÃO COMPARTILHA | K48: MANTER VIATURA | L48: 75054.508 | M48: =Tabela1[[#This Row],[Meta Hoje]]*Tabela1[[#This Row],[Reajuste]] -> 96820.316 | N48: =_xlfn.XLOOKUP(Tabela1[[#This Row],[Subprocesso]],Ajuste!A:A,Ajuste!B:B,0) -> 1.29
A49: NVR-RD-21D | B49: Pick Up Média 4x4 | C49: EMERGENCIA | D49: JEAN LIRA DE ARAUJO | E49: NOVA RUSSAS | F49: NOVA RUSSAS | G49: MOBILIZADA | H49: 46327 | I49: TJN7H18 | J49: COMPARTILHA | K49: DEVOLVER VIATURA | L49: 75054.508 | M49: =Tabela1[[#This Row],[Meta Hoje]]*Tabela1[[#This Row],[Reajuste]] -> 96820.316 | N49: =_xlfn.XLOOKUP(Tabela1[[#This Row],[Subprocesso]],Ajuste!A:A,Ajuste!B:B,0) -> 1.29
A50: NVI-RD-22B | B50: Pick Up Média 4x4 TAC | C50: EMERGENCIA | D50: JEAN LIRA DE ARAUJO | E50: NOVA RUSSAS | F50: NOVA RUSSAS | G50: MOBILIZADA | H50: NÃO | I50: TJN7H18 | J50: COMPARTILHA | K50: - | L50: 50702.296 | M50: =Tabela1[[#This Row],[Meta Hoje]]*Tabela1[[#This Row],[Reajuste]] -> 65405.961 | N50: =_xlfn.XLOOKUP(Tabela1[[#This Row],[Subprocesso]],Ajuste!A:A,Ajuste!B:B,0) -> 1.29
A51: CND-LM-21B | B51: Pick Up Leve 4x2 | C51: CORTE, RELIGA, LIGAÇÃO NOVA | D51: FELIPE PAIXAO DA SILVA | E51: CANINDE | F51: CANINDE | G51: MOBILIZADA | H51: NÃO | I51: TJP3C85 | J51: COMPARTILHA | K51: MANTER VIATURA | L51: 51105.432 | M51: =Tabela1[[#This Row],[Meta Hoje]]*Tabela1[[#This Row],[Reajuste]] -> 61837.573 | N51: =_xlfn.XLOOKUP(Tabela1[[#This Row],[Subprocesso]],Ajuste!A:A,Ajuste!B:B,0) -> 1.21
A52: CND-LM-26B | B52: Pick Up Leve 4x4 - Escada Central | C52: CORTE, RELIGA, LIGAÇÃO NOVA | D52: FELIPE PAIXAO DA SILVA | E52: CANINDE | F52: CANINDE | G52: MOBILIZADA | H52: NÃO | I52: TJS4F46 | J52: NÃO COMPARTILHA | K52: MANTER VIATURA | L52: 51105.432 | M52: =Tabela1[[#This Row],[Meta Hoje]]*Tabela1[[#This Row],[Reajuste]] -> 61837.573 | N52: =_xlfn.XLOOKUP(Tabela1[[#This Row],[Subprocesso]],Ajuste!A:A,Ajuste!B:B,0) -> 1.21
A53: CND-RD-21B | B53: Pick Up Média 4x4 | C53: EMERGENCIA | D53: SIDNEY DIAS BARROSO | E53: CANINDE | F53: CANINDE | G53: MOBILIZADA | H53: 46266 | I53: TJT6J51 | J53: COMPARTILHA | K53: MANTER VIATURA | L53: 75054.508 | M53: =Tabela1[[#This Row],[Meta Hoje]]*Tabela1[[#This Row],[Reajuste]] -> 96820.316 | N53: =_xlfn.XLOOKUP(Tabela1[[#This Row],[Subprocesso]],Ajuste!A:A,Ajuste!B:B,0) -> 1.29
A54: CND-RD-21C | B54: Pick Up Média 4x4 TAC | C54: EMERGENCIA | D54: SIDNEY DIAS BARROSO | E54: CANINDE | F54: CANINDE | G54: MOBILIZADA | H54: NÃO | I54: TJT6J51 | J54: COMPARTILHA | K54: MANTER VIATURA | L54: 75054.508 | M54: =Tabela1[[#This Row],[Meta Hoje]]*Tabela1[[#This Row],[Reajuste]] -> 96820.316 | N54: =_xlfn.XLOOKUP(Tabela1[[#This Row],[Subprocesso]],Ajuste!A:A,Ajuste!B:B,0) -> 1.29
A55: NVV-RD-22B | B55: Pick Up Média 4x4 TAC | C55: EMERGENCIA | D55: JEAN LIRA DE ARAUJO | E55: NOVA RUSSAS | F55: NOVA RUSSAS | G55: MOBILIZADA | H55: 46327 | I55: TJW2J71 | J55: NÃO COMPARTILHA | K55: MANTER VIATURA | L55: 50702.296 | M55: =Tabela1[[#This Row],[Meta Hoje]]*Tabela1[[#This Row],[Reajuste]] -> 65405.961 | N55: =_xlfn.XLOOKUP(Tabela1[[#This Row],[Subprocesso]],Ajuste!A:A,Ajuste!B:B,0) -> 1.29
A56: CNM-RD-21B | B56: Pick Up Média 4x4 | C56: EMERGENCIA | D56: SIDNEY DIAS BARROSO | E56: CANINDE | F56: MADALENA | G56: DESMOBILIZADA | H56: 46237 | I56: TKE1C48 | J56: DESMOBILIZADA | K56: DEVOLVER VIATURA | L56: 75054.508 | M56: =Tabela1[[#This Row],[Meta Hoje]]*Tabela1[[#This Row],[Reajuste]] -> 96820.316 | N56: =_xlfn.XLOOKUP(Tabela1[[#This Row],[Subprocesso]],Ajuste!A:A,Ajuste!B:B,0) -> 1.29
A57: QXD-LM-25B | B57: Pick Up Leve 4x2 | C57: CORTE, RELIGA, LIGAÇÃO NOVA | D57: DIEGO ALAN ANDRE BATISTA | E57: QUIXADA | F57: QUIXADÁ | G57: MOBILIZADA | H57: NÃO | I57: TJT9F43 | J57: COMPARTILHA | K57: MANTER VIATURA | L57: 51105.432 | M57: =Tabela1[[#This Row],[Meta Hoje]]*Tabela1[[#This Row],[Reajuste]] -> 61837.573 | N57: =_xlfn.XLOOKUP(Tabela1[[#This Row],[Subprocesso]],Ajuste!A:A,Ajuste!B:B,0) -> 1.21
A58: CNM-RD-21D | B58: Pick Up Média 4x4 | C58: EMERGENCIA | D58: SIDNEY DIAS BARROSO | E58: CANINDE | F58: MADALENA | G58: MOBILIZADA | H58: NÃO | I58: TKE1C48 | J58: NÃO COMPARTILHA | K58: - | L58: 75054.508 | M58: =Tabela1[[#This Row],[Meta Hoje]]*Tabela1[[#This Row],[Reajuste]] -> 96820.316 | N58: =_xlfn.XLOOKUP(Tabela1[[#This Row],[Subprocesso]],Ajuste!A:A,Ajuste!B:B,0) -> 1.29
A59: CNB-RD-21C | B59: Pick Up Média 4x4 | C59: EMERGENCIA | D59: SIDNEY DIAS BARROSO | E59: CANINDE | F59: BOA VIAGEM | G59: DESMOBILIZADA | H59: 46237 | I59: TKE1J44 | J59: DESMOBILIZADA | K59: MANTER VIATURA | L59: 75054.508 | M59: =Tabela1[[#This Row],[Meta Hoje]]*Tabela1[[#This Row],[Reajuste]] -> 96820.316 | N59: =_xlfn.XLOOKUP(Tabela1[[#This Row],[Subprocesso]],Ajuste!A:A,Ajuste!B:B,0) -> 1.29
A60: CNB-RD-21B | B60: Pick Up Média 4x4 | C60: EMERGENCIA | D60: SIDNEY DIAS BARROSO | E60: CANINDE | F60: BOA VIAGEM | G60: MOBILIZADA | H60: 46266 | I60: TKE1J44 | J60: NÃO COMPARTILHA | K60: MANTER VIATURA | L60: 75054.508 | M60: =Tabela1[[#This Row],[Meta Hoje]]*Tabela1[[#This Row],[Reajuste]] -> 96820.316 | N60: =_xlfn.XLOOKUP(Tabela1[[#This Row],[Subprocesso]],Ajuste!A:A,Ajuste!B:B,0) -> 1.29
A61: CNI-RD-21B | B61: Pick Up Média 4x4 | C61: EMERGENCIA | D61: SIDNEY DIAS BARROSO | E61: CANINDE | F61: AMANARI | G61: DESMOBILIZADA | H61: 46234 | I61: TKH4C80 | J61: DESMOBILIZADA | K61: DEVOLVER VIATURA | L61: 75054.508 | M61: =Tabela1[[#This Row],[Meta Hoje]]*Tabela1[[#This Row],[Reajuste]] -> 96820.316 | N61: =_xlfn.XLOOKUP(Tabela1[[#This Row],[Subprocesso]],Ajuste!A:A,Ajuste!B:B,0) -> 1.29
A62: CNI-RD-21C | B62: Pick Up Média 4x4 | C62: EMERGENCIA | D62: SIDNEY DIAS BARROSO | E62: CANINDE | F62: ITATIRA | G62: DESMOBILIZADA | H62: 46262 | I62: TKH4C80 | J62: DESMOBILIZADA | K62: - | L62: 75054.508 | M62: =Tabela1[[#This Row],[Meta Hoje]]*Tabela1[[#This Row],[Reajuste]] -> 96820.316 | N62: =_xlfn.XLOOKUP(Tabela1[[#This Row],[Subprocesso]],Ajuste!A:A,Ajuste!B:B,0) -> 1.29
...

Sheet Ajuste
A1: Subprocesso | B1: Ajuste
A2: CORTE, RELIGA, LIGAÇÃO NOVA | B2: 1.21
A3: MOTO CORTE | B3: 1.81
A4: GRUPO A | B4: 1.28
A5: EMERGENCIA | B5: 1.29

Sheet Plano Viaturas
A1: Placa | B1: Tipo de veículo | C1: Equipes vinculadas | D1: Qtd. equipes | E1: Compartilha? | F1: Datas de saída | G1: Última saída | H1: Situação após desmobilização | I1: Decisão final | J1: Observação
A2: TDU6A09 | B2: Pick Up Leve 4x2 | C2: CND-LM-28B | D2: 1 | E2: NÃO | H2: SEM SAÍDA PREVISTA | I2: A definir
A3: TDU6A92 | B3: Pick Up Leve 4x2 | C3: QXD-LM-24B | D3: 1 | E3: NÃO | H3: SEM SAÍDA PREVISTA | I3: A definir
A4: TDU6A93 | B4: Pick Up Leve 4x2 | C4: CND-LM-25B | D4: 1 | E4: NÃO | H4: SEM SAÍDA PREVISTA | I4: A definir
A5: TDU6A94 | B5: Moto | C5: CND-MO-22B | D5: 1 | E5: NÃO | H5: SEM SAÍDA PREVISTA | I5: A definir
A6: TDU6A95 | B6: Pick Up Leve 4x2 | C6: CAT-LM-25B | D6: 1 | E6: NÃO | H6: SEM SAÍDA PREVISTA | I6: A definir
A7: TDU6A96 | B7: Moto | C7: QXD-MO-23B | D7: 1 | E7: NÃO | H7: SEM SAÍDA PREVISTA | I7: A definir
A8: TDU6A97 | B8: Pick Up Leve 4x2 | C8: CND-LM-22B | D8: 1 | E8: NÃO | H8: SEM SAÍDA PREVISTA | I8: A definir
A9: TDU6A99 | B9: Pick Up Leve 4x2 | C9: NVR-LM-22B | D9: 1 | E9: NÃO | H9: SEM SAÍDA PREVISTA | I9: A definir
A10: TDU6B00 | B10: Pick Up Leve 4x4 - Escada Central | C10: CNB-LM-27B | D10: 1 | E10: NÃO | H10: SEM SAÍDA PREVISTA | I10: A definir
A11: TDU6B01 | B11: Pick Up Leve 4x2 | C11: CAT-LM-23B | D11: 1 | E11: NÃO | H11: SEM SAÍDA PREVISTA | I11: A definir
A12: TDU6B02 | B12: Moto | C12: NVR-MO-21B | D12: 1 | E12: NÃO | H12: SEM SAÍDA PREVISTA | I12: A definir
A13: TDU6B04 | B13: Pick Up Leve 4x2 | C13: NVR-LM-25B | D13: 1 | E13: NÃO | H13: SEM SAÍDA PREVISTA | I13: A definir
... A35: TES4E19 | B35: Caminhão SKY | C35: GRUPO A | D35: 1 | E35: NÃO | H35: SEM SAÍDA PREVISTA | I35: A definir
A36: TIZ7G43 | B36: Pick Up Média 4x4 | C36: NVM-RD-21B | D36: 1 | E36: NÃO | F36: Nov/26 | G36: 46327 | H36: FICA LIVRE APÓS ÚLTIMA SAÍDA | I36: A definir | J36: UTILIZAR NA MULTSKILL
A37: TJB4F14 | B37: Pick Up Média 4x4 | C37: QXD-RD-21D / QXD-RD-22B | D37: 2 | E37: SIM | F37: Oct/26 | G37: 46296 | H37: MANTER - AINDA HÁ EQUIPE | I37: A definir
A38: TJD1C62 | B38: Pick Up Média 4x4 | C38: NVV-RD-21B / NVV-RD-21C | D38: 2 | E38: SIM | F38: Nov/26 | G38: 46327 | H38: FICA LIVRE APÓS ÚLTIMA SAÍDA | I38: A definir | J38: UTILIZAR NA MULTSKILL
A39: TJD6E41 | B39: Pick Up Média 4x4 TAC | C39: QXD-RD-23B | D39: 1 | E39: SIM | F39: Oct/26 | G39: 46296 | H39: FICA LIVRE APÓS ÚLTIMA SAÍDA | I39: A definir | J39: UTILIZAR NA MULTSKILL
A40: TJF4F81 | B40: Pick Up Média 4x4 | C40: CAT-RD-23C | D40: 1 | E40: SIM | F40: Dec/26 | G40: 46357 | H40: FICA LIVRE APÓS ÚLTIMA SAÍDA | I40: A definir | J40: UTILIZAR NA MULTSKILL
A41: TJF6134 | B41: Pick Up Média 4x4 | C41: CND-RD-23B | D41: 1 | E41: SIM | F41: Aug/26 | G41: 46237 | H41: FICA LIVRE APÓS ÚLTIMA SAÍDA | I41: A definir | J41: UTILIZAR NA MULTSKILL
A42: TJF6I57 | B42: Pick Up Média 4x4 | C42: NVR-RD-21C / NVR-RD-23B | D42: 2 | E42: SIM | F42: Nov/26 | G42: 46327 | H42: FICA LIVRE APÓS ÚLTIMA SAÍDA | I42: A definir
A43: TJK3A62 | B43: Pick Up Média 4x4 | C43: CAT-RD-22C | D43: 1 | E43: SIM | F43: Dec/26 | G43: 46357 | H43: FICA LIVRE APÓS ÚLTIMA SAÍDA | I43: A definir
A44: TJN5B95 | B44: Pick Up Média 4x4 | C44: CAT-RD-21B | D44: 1 | E44: NÃO | H44: SEM SAÍDA PREVISTA | I44: A definir
A45: TJN7H18 | B45: Pick Up Média 4x4 / Pick Up Média 4x4 TAC | C45: NVR-RD-21D / NVI-RD-22B | D45: 2 | E45: SIM | F45: Nov/26 | G45: 46327 | H45: MANTER - AINDA HÁ EQUIPE | I45: A definir
A46: TJP3C85 | B46: Pick Up Leve 4x2 | C46: CND-LM-21B | D46: 1 | E46: SIM | H46: SEM SAÍDA PREVISTA | I46: A definir
A47: TJS4F46 | B47: Pick Up Leve 4x4 - Escada Central | C47: CND-LM-26B | D47: 1 | E47: NÃO | H47: SEM SAÍDA PREVISTA | I47: A definir
A48: TJT6J51 | B48: Pick Up Média 4x4 / Pick Up Média 4x4 TAC | C48: CND-RD-21B / CND-RD-21C | D48: 2 | E48: SIM | F48: Sep/26 | G48: 46266 | H48: MANTER - AINDA HÁ EQUIPE | I48: A definir
A49: TJT9F43 | B49: Pick Up Leve 4x2 | C49: QXD-LM-25B | D49: 1 | E49: SIM | H49: SEM SAÍDA PREVISTA | I49: A definir
A50: TJW2J71 | B50: Pick Up Média 4x4 TAC | C50: NVV-RD-22B | D50: 1 | E50: NÃO | F50: Nov/26 | G50: 46327 | H50: FICA LIVRE APÓS ÚLTIMA SAÍDA | I50: A definir
A51: TKE1C48 | B51: Pick Up Média 4x4 | C51: CNM-RD-21D / CNM-RD-21B | D51: 2 | E51: SIM | F51: Aug/26 | G51: 46237 | H51: MANTER - AINDA HÁ EQUIPE | I51: A definir
A52: TKE1J44 | B52: Pick Up Média 4x4 | C52: CNB-RD-21C / CNB-RD-21B | D52: 2 | E52: SIM | F52: Aug/26 / Sep/26 | G52: 46266 | H52: FICA LIVRE APÓS ÚLTIMA SAÍDA | I52: A definir
A53: TKH0I57 | B53: Pick Up Média 4x4 | C53: CAT-RD-21C | D53: 1 | E53: NÃO | H53: SEM SAÍDA PREVISTA | I53: A definir
A54: TKH4C80 | B54: Pick Up Média 4x4 | C54: CNI-RD-21B / CNI-RD-21C | D54: 2 | E54: SIM | F54: Jul/26 / Sep/26 | G54: 46266 | H54: FICA LIVRE APÓS ÚLTIMA SAÍDA | I54: A definir
A55: TKN2G17 | B55: Pick Up Média 4x4 | C55: NVR-RD-22B / NVR-RD-22C | D55: 2 | E55: SIM | F55: Nov/26 | G55: 46327 | H55: FICA LIVRE APÓS ÚLTIMA SAÍDA | I55: A definir
A56: TKO7B34 | B56: Pick Up Média 4x4 / Pick Up Média 4x4 TAC | C56: QXB-RD-21B / QXB-RD-21C | D56: 2 | E56: SIM | F56: Oct/26 | G56: 46296 | H56: MANTER - AINDA HÁ EQUIPE | I56: A definir
A57: TKQ8A66 | B57: Pick Up Média 4x4 | C57: QXB-RD-21D / QXB-RD-22B | D57: 2 | E57: SIM | F57: Oct/26 | G57: 46296 | H57: FICA LIVRE APÓS ÚLTIMA SAÍDA | I57: A definir
A58: TKR1A52 | B58: Pick Up Leve 4x2 | C58: QXD-LM-28B | D58: 1 | E58: NÃO | H58: SEM SAÍDA PREVISTA | I58: A definir
A59: TKU6B25 | B59: Pick Up Leve 4x2 | C59: NVR-LM-24B | D59: 1 | E59: NÃO | H59: SEM SAÍDA PREVISTA | I59: A definir
A60: TKV8C75 | B60: Pick Up Leve 4x4 - Escada Central | C60: QXD-LM-30B | D60: 1 | E60: NÃO | H60: SEM SAÍDA PREVISTA | I60: A definir
A61: TKX2B12 | B61: Pick Up Média 4x4 | C61: CND-RD-21D / CND-RD-22B | D61: 2 | E61: SIM | F61: Sep/26 | G61: 46266 | H61: MANTER - AINDA HÁ EQUIPE | I61: A definir
...

Sheet Viaturas
A1: Placa | B1: Modelo | C1: Equipe | D1: Staus | E1: Local Rodagem
A2: QTP9757 | B2: XTZ | C2: QXD-MO-23B | D2: Em operação | E2: =_xlfn.XLOOKUP(A2,[1]Dados!$C$13:$C$109,[1]Dados!$DQ$13:$DQ$109,0) -> CANINDÉ-CE
A3: QTP9837 | B3: XTZ | C3: Reserva | D3: Reserva | E3: =_xlfn.XLOOKUP(A3,[1]Dados!$C$13:$C$109,[1]Dados!$DQ$13:$DQ$109,0) -> CANINDÉ-CE
A4: QSL5J07 | B4: ACCELO | C4: Reserva | D4: Reserva | E4: =_xlfn.XLOOKUP(A4,[1]Dados!$C$13:$C$109,[1]Dados!$DQ$13:$DQ$109,0) -> CANINDÉ-CE
A5: TJN7H18 | B5: HILUX | C5: =_xlfn.XLOOKUP(A5,Tabela1[PLACA],Tabela1[Equipes],0) -> NVR-RD-21D | E5: =_xlfn.XLOOKUP(A5,[1]Dados!$C$13:$C$109,[1]Dados!$DQ$13:$DQ$109,0) -> NOVA RUSSAS-CE
A6: TLM2C64 | B6: HILUX | C6: =_xlfn.XLOOKUP(A6,Tabela1[PLACA],Tabela1[Equipes],0) -> NVI-RD-21B | E6: =_xlfn.XLOOKUP(A6,[1]Dados!$C$13:$C$109,[1]Dados!$DQ$13:$DQ$109,0) -> IPU-CE
A7: TJT9F43 | B7: HILUX | C7: =_xlfn.XLOOKUP(A7,Tabela1[PLACA],Tabela1[Equipes],0) -> QXD-LM-25B | E7: =_xlfn.XLOOKUP(A7,[1]Dados!$C$13:$C$109,[1]Dados!$DQ$13:$DQ$109,0) -> QUIXADÁ-CE
A8: TKH4C80 | B8: HILUX | C8: =_xlfn.XLOOKUP(A8,Tabela1[PLACA],Tabela1[Equipes],0) -> CNI-RD-21B | E8: =_xlfn.XLOOKUP(A8,[1]Dados!$C$13:$C$109,[1]Dados!$DQ$13:$DQ$109,0) -> CANINDÉ-CE
A9: TDU6B27 | B9: SAVEIRO | C9: =_xlfn.XLOOKUP(A9,Tabela1[PLACA],Tabela1[Equipes],0) -> QXD-LM-23B | E9: =_xlfn.XLOOKUP(A9,[1]Dados!$C$13:$C$109,[1]Dados!$DQ$13:$DQ$109,0) -> QUIXADÁ-CE
A10: TDU6B28 | B10: SAVEIRO | C10: =_xlfn.XLOOKUP(A10,Tabela1[PLACA],Tabela1[Equipes],0) -> CND-LM-23B | E10: =_xlfn.XLOOKUP(A10,[1]Dados!$C$13:$C$109,[1]Dados!$DQ$13:$DQ$109,0) -> CANINDÉ-CE
A11: TDU6B30 | B11: SAVEIRO | C11: =_xlfn.XLOOKUP(A11,Tabela1[PLACA],Tabela1[Equipes],0) -> NVR-LM-23B | E11: =_xlfn.XLOOKUP(A11,[1]Dados!$C$13:$C$109,[1]Dados!$DQ$13:$DQ$109,0) -> IPU-CE
A12: TDU6A98 | B12: SAVEIRO | C12: =_xlfn.XLOOKUP(A12,Tabela1[PLACA],Tabela1[Equipes],0) -> 0 | E12: =_xlfn.XLOOKUP(A12,[1]Dados!$C$13:$C$109,[1]Dados!$DQ$13:$DQ$109,0) -> CANINDÉ-CE
A13: TDU6A99 | B13: SAVEIRO | C13: =_xlfn.XLOOKUP(A13,Tabela1[PLACA],Tabela1[Equipes],0) -> NVR-LM-22B | E13: =_xlfn.XLOOKUP(A13,[1]Dados!$C$13:$C$109,[1]Dados!$DQ$13:$DQ$109,0) -> NOVA RUSSAS-CE
A14: TDU6B00 | B14: SAVEIRO | C14: =_xlfn.XLOOKUP(A14,Tabela1[PLACA],Tabela1[Equipes],0) -> CNB-LM-27B | E14: =_xlfn.XLOOKUP(A14,[1]Dados!$C$13:$C$109,[1]Dados!$DQ$13:$DQ$109,0) -> NOVA RUSSAS-CE
A15: TDU6B09 | B15: SAVEIRO | C15: =_xlfn.XLOOKUP(A15,Tabela1[PLACA],Tabela1[Equipes],0) -> 0 | E15: =_xlfn.XLOOKUP(A15,[1]Dados!$C$13:$C$109,[1]Dados!$DQ$13:$DQ$109,0) -> CANINDÉ-CE
A16: TDU6B41 | B16: SAVEIRO | C16: =_xlfn.XLOOKUP(A16,Tabela1[PLACA],Tabela1[Equipes],0) -> CND-MO-23B | E16: =_xlfn.XLOOKUP(A16,[1]Dados!$C$13:$C$109,[1]Dados!$DQ$13:$DQ$109,0) -> MADALENA-CE
... A30: TDU6A97 | B30: SAVEIRO | C30: =_xlfn.XLOOKUP(A30,Tabela1[PLACA],Tabela1[Equipes],0) -> CND-LM-22B | E30: =_xlfn.XLOOKUP(A30,[1]Dados!$C$13:$C$109,[1]Dados!$DQ$13:$DQ$109,0) -> CANINDÉ-CE
A31: TDU6B29 | B31: SAVEIRO | C31: Feitosa | E31: =_xlfn.XLOOKUP(A31,[1]Dados!$C$13:$C$109,[1]Dados!$DQ$13:$DQ$109,0) -> CANINDÉ-CE
A32: TDU6B32 | B32: SAVEIRO | C32: =_xlfn.XLOOKUP(A32,Tabela1[PLACA],Tabela1[Equipes],0) -> CNB-LM-24B | E32: =_xlfn.XLOOKUP(A32,[1]Dados!$C$13:$C$109,[1]Dados!$DQ$13:$DQ$109,0) -> CANINDÉ-CE
A33: TDU6B03 | B33: SAVEIRO | C33: Jean/Regis | E33: =_xlfn.XLOOKUP(A33,[1]Dados!$C$13:$C$109,[1]Dados!$DQ$13:$DQ$109,0) -> NOVA RUSSAS-CE
A34: TDU6B34 | B34: SAVEIRO | C34: =_xlfn.XLOOKUP(A34,Tabela1[PLACA],Tabela1[Equipes],0) -> CND-LM-30B | E34: =_xlfn.XLOOKUP(A34,[1]Dados!$C$13:$C$109,[1]Dados!$DQ$13:$DQ$109,0) -> CRATEÚS-CE
A35: TDU6B40 | B35: SAVEIRO | C35: =_xlfn.XLOOKUP(A35,Tabela1[PLACA],Tabela1[Equipes],0) -> QXD-MO-22B | E35: =_xlfn.XLOOKUP(A35,[1]Dados!$C$13:$C$109,[1]Dados!$DQ$13:$DQ$109,0) -> QUIXADÁ-CE
A36: TDU6B10 | B36: SAVEIRO | C36: =_xlfn.XLOOKUP(A36,Tabela1[PLACA],Tabela1[Equipes],0) -> QXB-LM-26B | E36: =_xlfn.XLOOKUP(A36,[1]Dados!$C$13:$C$109,[1]Dados!$DQ$13:$DQ$109,0) -> QUIXERAMOBIM-CE
A37: TDU6B11 | B37: SAVEIRO | C37: Reserva | D37: Reserva | E37: =_xlfn.XLOOKUP(A37,[1]Dados!$C$13:$C$109,[1]Dados!$DQ$13:$DQ$109,0) -> CANINDÉ-CE
A38: TDU6B15 | B38: SAVEIRO | C38: =_xlfn.XLOOKUP(A38,Tabela1[PLACA],Tabela1[Equipes],0) -> 0 | E38: =_xlfn.XLOOKUP(A38,[1]Dados!$C$13:$C$109,[1]Dados!$DQ$13:$DQ$109,0) -> CARIDADE-CE
A39: TDU6B16 | B39: SAVEIRO | C39: =_xlfn.XLOOKUP(A39,Tabela1[PLACA],Tabela1[Equipes],0) -> 0 | E39: =_xlfn.XLOOKUP(A39,[1]Dados!$C$13:$C$109,[1]Dados!$DQ$13:$DQ$109,0) -> QUIXADÁ-CE
A40: TDU6A95 | B40: SAVEIRO | C40: =_xlfn.XLOOKUP(A40,Tabela1[PLACA],Tabela1[Equipes],0) -> CAT-LM-25B | E40: =_xlfn.XLOOKUP(A40,[1]Dados!$C$13:$C$109,[1]Dados!$DQ$13:$DQ$109,0) -> CRATEÚS-CE
A41: TDU6B31 | B41: SAVEIRO | C41: =_xlfn.XLOOKUP(A41,Tabela1[PLACA],Tabela1[Equipes],0) -> NVR-LM-26B | E41: =_xlfn.XLOOKUP(A41,[1]Dados!$C$13:$C$109,[1]Dados!$DQ$13:$DQ$109,0) -> VARJOTA-CE
A42: TDU6B33 | B42: SAVEIRO | C42: =_xlfn.XLOOKUP(A42,Tabela1[PLACA],Tabela1[Equipes],0) -> NVQ-LM-30B | E42: =_xlfn.XLOOKUP(A42,[1]Dados!$C$13:$C$109,[1]Dados!$DQ$13:$DQ$109,0) -> CANINDÉ-CE
A43: TDU6B35 | B43: SAVEIRO | C43: =_xlfn.XLOOKUP(A43,Tabela1[PLACA],Tabela1[Equipes],0) -> NVR-LM-27B | E43: =_xlfn.XLOOKUP(A43,[1]Dados!$C$13:$C$109,[1]Dados!$DQ$13:$DQ$109,0) -> NOVA RUSSAS-CE
A44: TDU6B05 | B44: SAVEIRO | C44: =_xlfn.XLOOKUP(A44,Tabela1[PLACA],Tabela1[Equipes],0) -> 0 | E44: =_xlfn.XLOOKUP(A44,[1]Dados!$C$13:$C$109,[1]Dados!$DQ$13:$DQ$109,0) -> CRATEÚS-CE
A45: TDU6B37 | B45: SAVEIRO | C45: Felipe | E45: =_xlfn.XLOOKUP(A45,[1]Dados!$C$13:$C$109,[1]Dados!$DQ$13:$DQ$109,0) -> CANINDÉ-CE
A46: TDU6B08 | B46: SAVEIRO | C46: =_xlfn.XLOOKUP(A46,Tabela1[PLACA],Tabela1[Equipes],0) -> CAT-LM-24B | E46: =_xlfn.XLOOKUP(A46,[1]Dados!$C$13:$C$109,[1]Dados!$DQ$13:$DQ$109,0) -> CRATEÚS-CE
A47: TDU6B39 | B47: SAVEIRO | C47: =_xlfn.XLOOKUP(A47,Tabela1[PLACA],Tabela1[Equipes],0) -> NVR-LM-28B | E47: =_xlfn.XLOOKUP(A47,[1]Dados!$C$13:$C$109,[1]Dados!$DQ$13:$DQ$109,0) -> NOVA RUSSAS-CE
A48: TDU6B13 | B48: SAVEIRO | C48: =_xlfn.XLOOKUP(A48,Tabela1[PLACA],Tabela1[Equipes],0) -> 0 | E48: =_xlfn.XLOOKUP(A48,[1]Dados!$C$13:$C$109,[1]Dados!$DQ$13:$DQ$109,0) -> CRATEÚS-CE
A49: TDU6B14 | B49: SAVEIRO | C49: =_xlfn.XLOOKUP(A49,Tabela1[PLACA],Tabela1[Equipes],0) -> QXD-LM-29B | E49: =_xlfn.XLOOKUP(A49,[1]Dados!$C$13:$C$109,[1]Dados!$DQ$13:$DQ$109,0) -> QUIXADÁ-CE
A50: TDU6A94 | B50: SAVEIRO | C50: =_xlfn.XLOOKUP(A50,Tabela1[PLACA],Tabela1[Equipes],0) -> CND-MO-22B | E50: =_xlfn.XLOOKUP(A50,[1]Dados!$C$13:$C$109,[1]Dados!$DQ$13:$DQ$109,0) -> CANINDÉ-CE
A51: TOW6C53 | B51: CROSSER S ABS | C51: =_xlfn.XLOOKUP(A51,Tabela1[PLACA],Tabela1[Equipes],0) -> NVR-MO-23B | E51: =_xlfn.XLOOKUP(A51,[1]Dados!$C$13:$C$109,[1]Dados!$DQ$13:$DQ$109,0) -> NOVA RUSSAS-CE
A52: TOX1G03 | B52: CROSSER S ABS | C52: =_xlfn.XLOOKUP(A52,Tabela1[PLACA],Tabela1[Equipes],0) -> QXD-MO-21B | E52: =_xlfn.XLOOKUP(A52,[1]Dados!$C$13:$C$109,[1]Dados!$DQ$13:$DQ$109,0) -> QUIXADÁ-CE
A53: TOX1H13 | B53: CROSSER S ABS | C53: CAT-MO-21B | D53: Em operação | E53: =_xlfn.XLOOKUP(A53,[1]Dados!$C$13:$C$109,[1]Dados!$DQ$13:$DQ$109,0) -> CRATEÚS-CE
...

Sheet Resumo Mensal
A1: RESUMO MENSAL DA DESMOBILIZAÇÃO | M1: Valor atual | N1: Valor pós
K2: 6851379.5 | M2: 5276285 | N2: 3944192.8
A3: Mês | B3: Saída de Equipes | C3: Acumulado de saídas | D3: Equipes restantes | E3: Redução sem reequilíbrio (R$) | F3: Redução sem reequilíbrio acumulada (R$) | G3: Contrato restante sem reequilíbrio (R$) | H3: Contrato restante com reequilíbrio (R$)
A4: 46204 | B4: 1 | C4: 1 | D4: 87 | E4: 75054.508 | F4: =SUM(E4) -> 75054.508 | G4: =$M$2-F4 -> 5201230.5 | H4: =$K$2-Q4 -> 6754559.2 | P4: 96820.316 | Q4: =SUM(P4) -> 96820.316
A5: 46235 | B5: 3 | C5: 4 | D5: 84 | E5: 200811.31 | F5: =SUM(E4:E5) -> 275865.82 | G5: =$M$2-F5 -> 5000419.1 | H5: =$K$2-Q5 -> 6495512.6 | P5: 259046.59 | Q5: =SUM(P4:P5) -> 355866.91
A6: 46266 | B6: 4 | C6: 8 | D6: 80 | E6: 300218.03 | F6: =SUM(E4:E6) -> 576083.85 | G6: =$M$2-F6 -> 4700201.1 | H6: =$K$2-Q6 -> 6108231.3 | P6: 387281.26 | Q6: =SUM(P4:P6) -> 743148.17
A7: 46296 | B7: 8 | C7: 16 | D7: 72 | E7: 576083.85 | F7: =SUM(E4:E7) -> 1152167.7 | G7: =$M$2-F7 -> 4124117.3 | H7: =$K$2-Q7 -> 5365083.2 | P7: 743148.17 | Q7: =SUM(P4:P7) -> 1486296.3
A8: 46327 | B8: 11 | C8: 27 | D8: 61 | E8: 801247.38 | F8: =SUM(E4:E8) -> 1953415.1 | G8: =$M$2-F8 -> 3322869.9 | H8: =$K$2-Q8 -> 4331474 | P8: 1033609.1 | Q8: =SUM(P4:P8) -> 2519905.5
A9: 46357 | B9: 4 | C9: 31 | D9: 57 | E9: 300218.03 | F9: =SUM(E4:E9) -> 2253633.1 | G9: =$M$2-F9 -> 3022651.9 | H9: =$K$2-Q9 -> 3944192.8 | P9: 387281.26 | Q9: =SUM(P4:P9) -> 2907186.7
